Workbook

Sheet Summary
A1: How to use this
A2: One tab per tool. Fill in the yellow "Your call" column: Keep, Remove or Rebind.
A3: Example: Omarchy | Super + Shift + Y | YouTube | Your call = Remove | Notes = never use it.
A4: Omarchy: Omarchy / Hyprland, this machine. Grey rows: defaults you already removed or replaced.
A5: LazyVim: LazyVim on this machine (~/.config/nvim). Space is the leader key.
A6: Nvim: Your own Neovim config (~/dotfiles/nvim, the Mac setup). Space is the leader key.
A7: herdr: herdr 0.9.1 defaults plus your config. Every shortcut starts with Ctrl+B (shown as "Ctrl+B ▸").
A8: Yabai: skhd bindings for yabai on the Mac (~/dotfiles/yabai/.skhdrc). Grey rows are commented out.
A9: Generated 2026-10-07 by scripts/keyboard-shortcuts/refresh from the live Hyprland, LazyVim, Neovim, herdr and skhd configs.
A11: Omarchy — by group | B11: Shortcuts | C11: Keep | D11: Remove | E11: Rebind
A12: Windows & workspaces | B12: =COUNTIFS('Omarchy'!$D$2:$D$241,$A12) | C12: =COUNTIFS('Omarchy'!$D$2:$D$241,$A12,'Omarchy'!$G$2:$G$241,"Keep") | D12: =COUNTIFS('Omarchy'!$D$2:$D$241,$A12,'Omarchy'!$G$2:$G$241,"Remove") | E12: =COUNTIFS('Omarchy'!$D$2:$D$241,$A12,'Omarchy'!$G$2:$G$241,"Rebind")
A13: Apps | B13: =COUNTIFS('Omarchy'!$D$2:$D$241,$A13) | C13: =COUNTIFS('Omarchy'!$D$2:$D$241,$A13,'Omarchy'!$G$2:$G$241,"Keep") | D13: =COUNTIFS('Omarchy'!$D$2:$D$241,$A13,'Omarchy'!$G$2:$G$241,"Remove") | E13: =COUNTIFS('Omarchy'!$D$2:$D$241,$A13,'Omarchy'!$G$2:$G$241,"Rebind")
A14: Menus, capture & system | B14: =COUNTIFS('Omarchy'!$D$2:$D$241,$A14) | C14: =COUNTIFS('Omarchy'!$D$2:$D$241,$A14,'Omarchy'!$G$2:$G$241,"Keep") | D14: =COUNTIFS('Omarchy'!$D$2:$D$241,$A14,'Omarchy'!$G$2:$G$241,"Remove") | E14: =COUNTIFS('Omarchy'!$D$2:$D$241,$A14,'Omarchy'!$G$2:$G$241,"Rebind")
A15: Clipboard | B15: =COUNTIFS('Omarchy'!$D$2:$D$241,$A15) | C15: =COUNTIFS('Omarchy'!$D$2:$D$241,$A15,'Omarchy'!$G$2:$G$241,"Keep") | D15: =COUNTIFS('Omarchy'!$D$2:$D$241,$A15,'Omarchy'!$G$2:$G$241,"Remove") | E15: =COUNTIFS('Omarchy'!$D$2:$D$241,$A15,'Omarchy'!$G$2:$G$241,"Rebind")
A16: Dictation | B16: =COUNTIFS('Omarchy'!$D$2:$D$241,$A16) | C16: =COUNTIFS('Omarchy'!$D$2:$D$241,$A16,'Omarchy'!$G$2:$G$241,"Keep") | D16: =COUNTIFS('Omarchy'!$D$2:$D$241,$A16,'Omarchy'!$G$2:$G$241,"Remove") | E16: =COUNTIFS('Omarchy'!$D$2:$D$241,$A16,'Omarchy'!$G$2:$G$241,"Rebind")
A17: Yours | B17: =COUNTIFS('Omarchy'!$D$2:$D$241,$A17) | C17: =COUNTIFS('Omarchy'!$D$2:$D$241,$A17,'Omarchy'!$G$2:$G$241,"Keep") | D17: =COUNTIFS('Omarchy'!$D$2:$D$241,$A17,'Omarchy'!$G$2:$G$241,"Remove") | E17: =COUNTIFS('Omarchy'!$D$2:$D$241,$A17,'Omarchy'!$G$2:$G$241,"Rebind")
A18: Volume, media & brightness | B18: =COUNTIFS('Omarchy'!$D$2:$D$241,$A18) | C18: =COUNTIFS('Omarchy'!$D$2:$D$241,$A18,'Omarchy'!$G$2:$G$241,"Keep") | D18: =COUNTIFS('Omarchy'!$D$2:$D$241,$A18,'Omarchy'!$G$2:$G$241,"Remove") | E18: =COUNTIFS('Omarchy'!$D$2:$D$241,$A18,'Omarchy'!$G$2:$G$241,"Rebind")
A19: Total | B19: =SUM(B12:B18) | C19: =SUM(C12:C18) | D19: =SUM(D12:D18) | E19: =SUM(E12:E18)
A21: LazyVim — by category | B21: Shortcuts | C21: Keep | D21: Remove | E21: Rebind
A22: Space: Other | B22: =COUNTIFS('LazyVim'!$E$2:$E$313,$A22) | C22: =COUNTIFS('LazyVim'!$E$2:$E$313,$A22,'LazyVim'!$G$2:$G$313,"Keep") | D22: =COUNTIFS('LazyVim'!$E$2:$E$313,$A22,'LazyVim'!$G$2:$G$313,"Remove") | E22: =COUNTIFS('LazyVim'!$E$2:$E$313,$A22,'LazyVim'!$G$2:$G$313,"Rebind")
A23: Ctrl / Alt keys | B23: =COUNTIFS('LazyVim'!$E$2:$E$313,$A23) | C23: =COUNTIFS('LazyVim'!$E$2:$E$313,$A23,'LazyVim'!$G$2:$G$313,"Keep") | D23: =COUNTIFS('LazyVim'!$E$2:$E$313,$A23,'LazyVim'!$G$2:$G$313,"Remove") | E23: =COUNTIFS('LazyVim'!$E$2:$E$313,$A23,'LazyVim'!$G$2:$G$313,"Rebind")
A24: Jump next / previous | B24: =COUNTIFS('LazyVim'!$E$2:$E$313,$A24) | C24: =COUNTIFS('LazyVim'!$E$2:$E$313,$A24,'LazyVim'!$G$2:$G$313,"Keep") | D24: =COUNTIFS('LazyVim'!$E$2:$E$313,$A24,'LazyVim'!$G$2:$G$313,"Remove") | E24: =COUNTIFS('LazyVim'!$E$2:$E$313,$A24,'LazyVim'!$G$2:$G$313,"Rebind")
A25: Other | B25: =COUNTIFS('LazyVim'!$E$2:$E$313,$A25) | C25: =COUNTIFS('LazyVim'!$E$2:$E$313,$A25,'LazyVim'!$G$2:$G$313,"Keep") | D25: =COUNTIFS('LazyVim'!$E$2:$E$313,$A25,'LazyVim'!$G$2:$G$313,"Remove") | E25: =COUNTIFS('LazyVim'!$E$2:$E$313,$A25,'LazyVim'!$G$2:$G$313,"Rebind")
A26: Space: Buffers | B26: =COUNTIFS('LazyVim'!$E$2:$E$313,$A26) | C26: =COUNTIFS('LazyVim'!$E$2:$E$313,$A26,'LazyVim'!$G$2:$G$313,"Keep") | D26: =COUNTIFS('LazyVim'!$E$2:$E$313,$A26,'LazyVim'!$G$2:$G$313,"Remove") | E26: =COUNTIFS('LazyVim'!$E$2:$E$313,$A26,'LazyVim'!$G$2:$G$313,"Rebind")
A27: Space: Code | B27: =COUNTIFS('LazyVim'!$E$2:$E$313,$A27) | C27: =COUNTIFS('LazyVim'!$E$2:$E$313,$A27,'LazyVim'!$G$2:$G$313,"Keep") | D27: =COUNTIFS('LazyVim'!$E$2:$E$313,$A27,'LazyVim'!$G$2:$G$313,"Remove") | E27: =COUNTIFS('LazyVim'!$E$2:$E$313,$A27,'LazyVim'!$G$2:$G$313,"Rebind")
A28: Space: Diagnostics / quickfix | B28: =COUNTIFS('LazyVim'!$E$2:$E$313,$A28) | C28: =COUNTIFS('LazyVim'!$E$2:$E$313,$A28,'LazyVim'!$G$2:$G$313,"Keep") | D28: =COUNTIFS('LazyVim'!$E$2:$E$313,$A28,'LazyVim'!$G$2:$G$313,"Remove") | E28: =COUNTIFS('LazyVim'!$E$2:$E$313,$A28,'LazyVim'!$G$2:$G$313,"Rebind")
A29: Space: Files / find | B29: =COUNTIFS('LazyVim'!$E$2:$E$313,$A29) | C29: =COUNTIFS('LazyVim'!$E$2:$E$313,$A29,'LazyVim'!$G$2:$G$313,"Keep") | D29: =COUNTIFS('LazyVim'!$E$2:$E$313,$A29,'LazyVim'!$G$2:$G$313,"Remove") | E29: =COUNTIFS('LazyVim'!$E$2:$E$313,$A29,'LazyVim'!$G$2:$G$313,"Rebind")
A30: Space: Git | B30: =COUNTIFS('LazyVim'!$E$2:$E$313,$A30) | C30: =COUNTIFS('LazyVim'!$E$2:$E$313,$A30,'LazyVim'!$G$2:$G$313,"Keep") | D30: =COUNTIFS('LazyVim'!$E$2:$E$313,$A30,'LazyVim'!$G$2:$G$313,"Remove") | E30: =COUNTIFS('LazyVim'!$E$2:$E$313,$A30,'LazyVim'!$G$2:$G$313,"Rebind")
A31: Space: Quit / session | B31: =COUNTIFS('LazyVim'!$E$2:$E$313,$A31) | C31: =COUNTIFS('LazyVim'!$E$2:$E$313,$A31,'LazyVim'!$G$2:$G$313,"Keep") | D31: =COUNTIFS('LazyVim'!$E$2:$E$313,$A31,'LazyVim'!$G$2:$G$313,"Remove") | E31: =COUNTIFS('LazyVim'!$E$2:$E$313,$A31,'LazyVim'!$G$2:$G$313,"Rebind")
A32: Space: Tabs | B32: =COUNTIFS('LazyVim'!$E$2:$E$313,$A32) | C32: =COUNTIFS('LazyVim'!$E$2:$E$313,$A32,'LazyVim'!$G$2:$G$313,"Keep") | D32: =COUNTIFS('LazyVim'!$E$2:$E$313,$A32,'LazyVim'!$G$2:$G$313,"Remove") | E32: =COUNTIFS('LazyVim'!$E$2:$E$313,$A32,'LazyVim'!$G$2:$G$313,"Rebind")
A33: Space: UI toggles | B33: =COUNTIFS('LazyVim'!$E$2:$E$313,$A33) | C33: =COUNTIFS('LazyVim'!$E$2:$E$313,$A33,'LazyVim'!$G$2:$G$313,"Keep") | D33: =COUNTIFS('LazyVim'!$E$2:$E$313,$A33,'LazyVim'!$G$2:$G$313,"Remove") | E33: =COUNTIFS('LazyVim'!$E$2:$E$313,$A33,'LazyVim'!$G$2:$G$313,"Rebind")
... A40: Auto-pairs while typing | B40: =COUNTIFS('LazyVim'!$E$2:$E$313,$A40) | C40: =COUNTIFS('LazyVim'!$E$2:$E$313,$A40,'LazyVim'!$G$2:$G$313,"Keep") | D40: =COUNTIFS('LazyVim'!$E$2:$E$313,$A40,'LazyVim'!$G$2:$G$313,"Remove") | E40: =COUNTIFS('LazyVim'!$E$2:$E$313,$A40,'LazyVim'!$G$2:$G$313,"Rebind")
A41: Total | B41: =SUM(B22:B40) | C41: =SUM(C22:C40) | D41: =SUM(D22:D40) | E41: =SUM(E22:E40)
A43: Nvim — by category | B43: Shortcuts | C43: Keep | D43: Remove | E43: Rebind
A44: Ctrl / Alt keys | B44: =COUNTIFS('Nvim'!$E$2:$E$254,$A44) | C44: =COUNTIFS('Nvim'!$E$2:$E$254,$A44,'Nvim'!$G$2:$G$254,"Keep") | D44: =COUNTIFS('Nvim'!$E$2:$E$254,$A44,'Nvim'!$G$2:$G$254,"Remove") | E44: =COUNTIFS('Nvim'!$E$2:$E$254,$A44,'Nvim'!$G$2:$G$254,"Rebind")
A45: Jump next / previous | B45: =COUNTIFS('Nvim'!$E$2:$E$254,$A45) | C45: =COUNTIFS('Nvim'!$E$2:$E$254,$A45,'Nvim'!$G$2:$G$254,"Keep") | D45: =COUNTIFS('Nvim'!$E$2:$E$254,$A45,'Nvim'!$G$2:$G$254,"Remove") | E45: =COUNTIFS('Nvim'!$E$2:$E$254,$A45,'Nvim'!$G$2:$G$254,"Rebind")
A46: Other | B46: =COUNTIFS('Nvim'!$E$2:$E$254,$A46) | C46: =COUNTIFS('Nvim'!$E$2:$E$254,$A46,'Nvim'!$G$2:$G$254,"Keep") | D46: =COUNTIFS('Nvim'!$E$2:$E$254,$A46,'Nvim'!$G$2:$G$254,"Remove") | E46: =COUNTIFS('Nvim'!$E$2:$E$254,$A46,'Nvim'!$G$2:$G$254,"Rebind")
A47: Space: Document / debug | B47: =COUNTIFS('Nvim'!$E$2:$E$254,$A47) | C47: =COUNTIFS('Nvim'!$E$2:$E$254,$A47,'Nvim'!$G$2:$G$254,"Keep") | D47: =COUNTIFS('Nvim'!$E$2:$E$254,$A47,'Nvim'!$G$2:$G$254,"Remove") | E47: =COUNTIFS('Nvim'!$E$2:$E$254,$A47,'Nvim'!$G$2:$G$254,"Rebind")
A48: Space: Other | B48: =COUNTIFS('Nvim'!$E$2:$E$254,$A48) | C48: =COUNTIFS('Nvim'!$E$2:$E$254,$A48,'Nvim'!$G$2:$G$254,"Keep") | D48: =COUNTIFS('Nvim'!$E$2:$E$254,$A48,'Nvim'!$G$2:$G$254,"Remove") | E48: =COUNTIFS('Nvim'!$E$2:$E$254,$A48,'Nvim'!$G$2:$G$254,"Rebind")
A49: Space: Rename / restart | B49: =COUNTIFS('Nvim'!$E$2:$E$254,$A49) | C49: =COUNTIFS('Nvim'!$E$2:$E$254,$A49,'Nvim'!$G$2:$G$254,"Keep") | D49: =COUNTIFS('Nvim'!$E$2:$E$254,$A49,'Nvim'!$G$2:$G$254,"Remove") | E49: =COUNTIFS('Nvim'!$E$2:$E$254,$A49,'Nvim'!$G$2:$G$254,"Rebind")
...

Sheet Omarchy
A1: # | B1: Shortcut | C1: What it does | D1: Group | E1: Set by | F1: Status | G1: Your call | H1: Notes
A2: 1 | B2: Super + Left | C2: Focus on left window | D2: Windows & workspaces | E2: Omarchy | F2: Active
A3: 2 | B3: Super + Right | C3: Focus on right window | D3: Windows & workspaces | E3: Omarchy | F3: Active
A4: 3 | B4: Super + Up | C4: Focus on above window | D4: Windows & workspaces | E4: Omarchy | F4: Active
A5: 4 | B5: Super + Down | C5: Focus on below window | D5: Windows & workspaces | E5: Omarchy | F5: Active
A6: 5 | B6: Super + 1 | C6: Switch to workspace 1 | D6: Windows & workspaces | E6: Omarchy | F6: Active
A7: 6 | B7: Super + Shift + 1 | C7: Move window to workspace 1 | D7: Windows & workspaces | E7: Omarchy | F7: Active
A8: 7 | B8: Super + Shift + Alt + 1 | C8: Move window silently to workspace 1 | D8: Windows & workspaces | E8: Omarchy | F8: Active
A9: 8 | B9: Super + 2 | C9: Switch to workspace 2 | D9: Windows & workspaces | E9: Omarchy | F9: Active
A10: 9 | B10: Super + Shift + 2 | C10: Move window to workspace 2 | D10: Windows & workspaces | E10: Omarchy | F10: Active
A11: 10 | B11: Super + Shift + Alt + 2 | C11: Move window silently to workspace 2 | D11: Windows & workspaces | E11: Omarchy | F11: Active
A12: 11 | B12: Super + 3 | C12: Switch to workspace 3 | D12: Windows & workspaces | E12: Omarchy | F12: Active
A13: 12 | B13: Super + Shift + 3 | C13: Move window to workspace 3 | D13: Windows & workspaces | E13: Omarchy | F13: Active
... A74: 73 | B74: Super + A | C74: Universal select all | D74: Yours | E74: You | F74: Active
A75: 74 | B75: Super + S | C75: Universal save | D75: Yours | E75: You | F75: Active | H75: Replaces an Omarchy default
A76: 75 | B76: Super + Shift + F | C76: File manager (cwd) | D76: Yours | E76: You | F76: Active | H76: Replaces an Omarchy default
A77: 76 | B77: Super + , | C77: Dismiss all notifications | D77: Yours | E77: You | F77: Active | H77: Replaces an Omarchy default
A78: 77 | B78: Super + Ctrl + 4 | C78: Screenshot | D78: Yours | E78: You | F78: Active | H78: Replaces an Omarchy default
A79: 78 | B79: Super + Ctrl + 5 | C79: Screenrecording | D79: Yours | E79: You | F79: Active | H79: Replaces an Omarchy default
A80: 79 | B80: Super + Ctrl + 6 | C80: Color picker | D80: Yours | E80: You | F80: Active | H80: Replaces an Omarchy default
A81: 80 | B81: Super + Shift + M | C81: Apple Music | D81: Yours | E81: You | F81: Active | H81: Replaces an Omarchy default
A82: 81 | B82: PowerOff key | C82: Power menu | D82: Menus, capture & system | E82: Omarchy | F82: Active
A83: 82 | B83: Laptop lid closed | C83: Runs omarchy-system-lid-close | D83: Menus, capture & system | E83: Omarchy | F83: Active
A84: 83 | B84: Laptop lid opened | C84: Runs omarchy-hyprland-monitor-clamshell | D84: Menus, capture & system | E84: Omarchy | F84: Active
A85: 84 | B85: AudioRaiseVolume key | C85: Volume up | D85: Volume, media & brightness | E85: Omarchy | F85: Active
A86: 85 | B86: AudioLowerVolume key | C86: Volume down | D86: Volume, media & brightness | E86: Omarchy | F86: Active
A87: 86 | B87: AudioMute key | C87: Mute | D87: Volume, media & brightness | E87: Omarchy | F87: Active
A88: 87 | B88: AudioMicMute key | C88: Mute microphone | D88: Volume, media & brightness | E88: Omarchy | F88: Active
A89: 88 | B89: Alt + AudioRaiseVolume key | C89: Volume up precise | D89: Volume, media & brightness | E89: Omarchy | F89: Active
A90: 89 | B90: Alt + AudioLowerVolume key | C90: Volume down precise | D90: Volume, media & brightness | E90: Omarchy | F90: Active
A91: 90 | B91: MonBrightnessUp key | C91: Brightness up | D91: Yours | E91: You | F91: Active | H91: Replaces an Omarchy default
A92: 91 | B92: MonBrightnessDown key | C92: Brightness down | D92: Yours | E92: You | F92: Active | H92: Replaces an Omarchy default
A93: 92 | B93: Shift + MonBrightnessUp key | C93: Brightness maximum | D93: Yours | E93: You | F93: Active | H93: Replaces an Omarchy default
A94: 93 | B94: Shift + MonBrightnessDown key | C94: Brightness minimum | D94: Yours | E94: You | F94: Active | H94: Replaces an Omarchy default
A95: 94 | B95: Alt + MonBrightnessUp key | C95: Brightness up precise | D95: Yours | E95: You | F95: Active | H95: Replaces an Omarchy default
A96: 95 | B96: Alt + MonBrightnessDown key | C96: Brightness down precise | D96: Yours | E96: You | F96: Active | H96: Replaces an Omarchy default
A97: 96 | B97: Super + W | C97: Close window | D97: Windows & workspaces | E97: Omarchy | F97: Removed by you
A98: 97 | B98: Ctrl + Alt + Delete | C98: Close all windows | D98: Windows & workspaces | E98: Omarchy | F98: Removed by you | G98: remove
A99: 98 | B99: Super + J | C99: Toggle window split | D99: Windows & workspaces | E99: Omarchy | F99: Removed by you | G99: remove
A100: 99 | B100: Super + P | C100: Pseudo window | D100: Windows & workspaces | E100: Omarchy | F100: Removed by you | G100: remove
...

Sheet LazyVim
A1: # | B1: Keys | C1: Mode | D1: What it does | E1: Category | F1: Comes from | G1: Your call | H1: Notes
A2: 1 | B2: Space w | C2: Normal | D2: Close buffer | E2: Space: Other | F2: Yours
A3: 2 | B3: Alt+J | C3: Normal, Visual, Select, Insert | D3: Move Down | E3: Ctrl / Alt keys | F3: LazyVim
A4: 3 | B4: Alt+K | C4: Normal, Visual, Select, Insert | D4: Move Up | E4: Ctrl / Alt keys | F4: LazyVim
A5: 4 | B5: Ctrl+/ | C5: Normal, Terminal | D5: Terminal (Root Dir) | E5: Ctrl / Alt keys | F5: LazyVim
A6: 5 | B6: Ctrl+_ | C6: Normal, Terminal | D6: Alias of Ctrl+/ (terminals send Ctrl+/ as Ctrl+_) | E6: Ctrl / Alt keys | F6: LazyVim
A7: 6 | B7: Ctrl+Down | C7: Normal | D7: Decrease Window Height | E7: Ctrl / Alt keys | F7: LazyVim
A8: 7 | B8: Ctrl+H | C8: Normal | D8: Go to Left Window | E8: Ctrl / Alt keys | F8: LazyVim
A9: 8 | B9: Ctrl+K | C9: Normal | D9: Go to Upper Window | E9: Ctrl / Alt keys | F9: LazyVim
A10: 9 | B10: Ctrl+L | C10: Normal | D10: Go to Right Window | E10: Ctrl / Alt keys | F10: LazyVim
A11: 10 | B11: Ctrl+Left | C11: Normal | D11: Decrease Window Width | E11: Ctrl / Alt keys | F11: LazyVim
A12: 11 | B12: Ctrl+Right | C12: Normal | D12: Increase Window Width | E12: Ctrl / Alt keys | F12: LazyVim
A13: 12 | B13: Ctrl+S | C13: Normal, Visual, Select, Insert | D13: Save File | E13: Ctrl / Alt keys | F13: LazyVim
... A313: 312 | B313: } | C313: Insert, Command line | D313: Close action for "{}" pair | E313: Auto-pairs while typing | F313: mini.pairs (auto-pairs)

Sheet Nvim
A1: # | B1: Keys | C1: Mode | D1: What it does | E1: Category | F1: Comes from | G1: Your call | H1: Notes
A2: 1 | B2: Ctrl+H | C2: Normal | D2: Move to left window | E2: Ctrl / Alt keys | F2: Yours: lua/config/keymaps.lua
A3: 2 | B3: Ctrl+K | C3: Normal | D3: Move to top window | E3: Ctrl / Alt keys | F3: Yours: lua/config/keymaps.lua
A4: 3 | B4: Ctrl+L | C4: Normal | D4: Move to right window | E4: Ctrl / Alt keys | F4: Yours: lua/config/keymaps.lua
A5: 4 | B5: Ctrl+S | C5: Normal, Visual, Select, Insert | D5: Save file | E5: Ctrl / Alt keys | F5: Yours: lua/config/keymaps.lua
A6: 5 | B6: Ctrl+W | C6: Normal | D6: Close buffer, keep layout | E6: Ctrl / Alt keys | F6: Yours: lua/config/keymaps.lua
A7: 6 | B7: [ d | C7: Normal | D7: Go to previous diagnostic message | E7: Jump next / previous | F7: Yours: lua/config/keymaps.lua
A8: 7 | B8: ] d | C8: Normal | D8: Go to next diagnostic message | E8: Jump next / previous | F8: Yours: lua/config/keymaps.lua
A9: 8 | B9: , , | C9: Normal, Insert | D9: Add comma at end | E9: Other | F9: Yours: lua/config/keymaps.lua
A10: 9 | B10: . . | C10: Normal | D10: Add period at end | E10: Other | F10: Yours: lua/config/keymaps.lua
A11: 10 | B11: ; | C11: Normal | D11: Command mode | E11: Other | F11: Yours: lua/config/keymaps.lua
A12: 11 | B12: ; ; | C12: Normal, Insert | D12: Add semicolon at end | E12: Other | F12: Yours: lua/config/keymaps.lua
A13: 12 | B13: Ctrl+J | C13: Normal | D13: Move to bottom window | E13: Other | F13: Yours: lua/config/keymaps.lua
... A93: 92 | B93: Space s w | C93: Normal | D93: [S]earch current [W]ord | E93: Space: Search | F93: Yours: lua/custom/plugins/snacks.lua
A94: 93 | B94: # | C94: Normal | D94: Search word under cursor (backwards) | E94: Vim motion (description only) | F94: Yours: lua/config/vim-motions.lua | H94: Maps the key to itself so it shows up in keymap search. Removing it only drops the description.
A95: 94 | B95: $ | C95: Normal | D95: Move to end of line | E95: Vim motion (description only) | F95: Yours: lua/config/vim-motions.lua | H95: Maps the key to itself so it shows up in keymap search. Removing it only drops the description.
A96: 95 | B96: % | C96: Normal | D96: Jump to matching bracket | E96: Vim motion (description only) | F96: Yours: lua/config/vim-motions.lua | H96: Maps the key to itself so it shows up in keymap search. Removing it only drops the description.
A97: 96 | B97: * | C97: Normal | D97: Search word under cursor | E97: Vim motion (description only) | F97: Yours: lua/config/vim-motions.lua | H97: Maps the key to itself so it shows up in keymap search. Removing it only drops the description.
A98: 97 | B98: . | C98: Normal | D98: Repeat last change | E98: Vim motion (description only) | F98: Yours: lua/config/vim-motions.lua | H98: Maps the key to itself so it shows up in keymap search. Removing it only drops the description.
A99: 98 | B99: / | C99: Normal | D99: Search forward | E99: Vim motion (description only) | F99: Yours: lua/config/vim-motions.lua | H99: Maps the key to itself so it shows up in keymap search. Removing it only drops the description.
A100: 99 | B100: 0 | C100: Normal | D100: Move to start of line | E100: Vim motion (description only) | F100: Yours: lua/config/vim-motions.lua | H100: Maps the key to itself so it shows up in keymap search. Removing it only drops the description.
A101: 100 | B101: ? | C101: Normal | D101: Search backward | E101: Vim motion (description only) | F101: Yours: lua/config/vim-motions.lua | H101: Maps the key to itself so it shows up in keymap search. Removing it only drops the description.
A102: 101 | B102: ^ | C102: Normal | D102: Move to first non-blank | E102: Vim motion (description only) | F102: Yours: lua/config/vim-motions.lua | H102: Maps the key to itself so it shows up in keymap search. Removing it only drops the description.
A103: 102 | B103: A | C103: Normal | D103: Append at end of line | E103: Vim motion (description only) | F103: Yours: lua/config/vim-motions.lua | H103: Maps the key to itself so it shows up in keymap search. Removing it only drops the description.
A104: 103 | B104: b | C104: Normal | D104: Move to previous word | E104: Vim motion (description only) | F104: Yours: lua/config/vim-motions.lua | H104: Maps the key to itself so it shows up in keymap search. Removing it only drops the description.
A105: 104 | B105: C | C105: Normal | D105: Change to end of line | E105: Vim motion (description only) | F105: Yours: lua/config/vim-motions.lua | H105: Maps the key to itself so it shows up in keymap search. Removing it only drops the description.
... A147: 146 | B147: z z | C147: Normal | D147: Center cursor on screen | E147: Vim motion (description only) | F147: Yours: lua/config/vim-motions.lua | H147: Maps the key to itself so it shows up in keymap search. Removing it only drops the description.
A148: 147 | B148: Enter | C148: Insert | D148: autopairs completion confirm | E148: Other | F148: nvim-autopairs (plugin default)
A149: 148 | B149: Ctrl+G S | C149: Insert | D149: Add a surrounding pair around the cursor, on new lines (insert mode) | E149: Ctrl / Alt keys | F149: nvim-surround (plugin default)
A150: 149 | B150: Ctrl+G s | C150: Insert | D150: Add a surrounding pair around the cursor (insert mode) | E150: Ctrl / Alt keys | F150: nvim-surround (plugin default)
A151: 150 | B151: c S | C151: Normal | D151: Change a surrounding pair, putting replacements on new lines | E151: Other | F151: nvim-surround (plugin default)
A152: 151 | B152: c s | C152: Normal | D152: Change a surrounding pair | E152: Other | F152: nvim-surround (plugin default)
A153: 152 | B153: d s | C153: Normal | D153: Delete a surrounding pair | E153: Other | F153: nvim-surround (plugin default)
A154: 153 | B154: S | C154: Visual | D154: Add a surrounding pair around a visual selection | E154: Other | F154: nvim-surround (plugin default)
A155: 154 | B155: y S | C155: Normal | D155: Add a surrounding pair around a motion, on new lines (normal mode) | E155: Other | F155: nvim-surround (plugin default)
A156: 155 | B156: y s | C156: Normal | D156: Add a surrounding pair around a motion (normal mode) | E156: Other | F156: nvim-surround (plugin default)
A157: 156 | B157: y S S | C157: Normal | D157: Add a surrounding pair around the current line, on new lines (normal mode) | E157: Other | F157: nvim-surround (plugin default)
A158: 157 | B158: y s s | C158: Normal | D158: Add a surrounding pair around the current line (normal mode) | E158: Other | F158: nvim-surround (plugin default)
A159: 158 | B159: g S | C159: Visual | D159: Add a surrounding pair around a visual selection, on new lines | E159: g commands | F159: nvim-surround (plugin default)
... A254: 253 | B254: g % | C254: Motion | D254: <Plug>(MatchitOperationBackward) | E254: Neovim built-in | F254: Neovim built-in (matchit)

Sheet herdr
A1: # | B1: Keys | C1: Setting name | D1: What it does | E1: Group | F1: Set by | G1: Status | H1: Your call | I1: Notes
A2: 1 | B2: Ctrl+B | C2: prefix | D2: The prefix key every other herdr shortcut starts with | E2: Session & app | F2: herdr | G2: Active
A3: 2 | B3: Ctrl+B ▸ ? | C3: help | D3: Show keybinding help | E3: Session & app | F3: herdr | G3: Active
A4: 3 | B4: Ctrl+B ▸ S | C4: settings | D4: Open settings | E4: Session & app | F4: herdr | G4: Active
A5: 4 | B5: Ctrl+B ▸ Q | C5: detach | D5: Detach from the session (it keeps running) | E5: Session & app | F5: herdr | G5: Active
A6: 5 | B6: Ctrl+B ▸ Shift+R | C6: reload_config | D6: Reload config.toml | E6: Session & app | F6: herdr | G6: Active
A7: 6 | B7: Ctrl+B ▸ O | C7: open_notification_target | D7: Jump to the pane behind the latest notification | E7: Session & app | F7: herdr | G7: Active
A8: 7 | B8: Ctrl+V | C8: remote_image_paste | D8: Paste an image over herdr --remote | E8: Session & app | F8: herdr | G8: Active | I8: only active in herdr --remote; empty disables raw-key image paste
A9: 8 | B9: Ctrl+B ▸ E | C9: edit_scrollback | D9: Open the pane's scrollback in your editor | E9: Session & app | F9: herdr | G9: Active
A10: 9 | B10: Ctrl+B ▸ B | C10: toggle_sidebar | D10: Toggle the sidebar | E10: Session & app | F10: herdr | G10: Active
A11: 10 | B11: Ctrl+B ▸ W | C11: workspace_picker | D11: Open the workspace picker | E11: Workspaces | F11: herdr | G11: Active
A12: 11 | B12: Ctrl+B ▸ G | C12: goto | D12: Go-to picker | E12: Workspaces | F12: herdr | G12: Active
A13: 12 | B13: Ctrl+B ▸ Shift+N | C13: new_workspace | D13: New workspace | E13: Workspaces | F13: herdr | G13: Active
A14: 13 | B14: Ctrl+B ▸ Shift+G | C14: new_worktree | D14: New git worktree workspace | E14: Workspaces | F14: herdr | G14: Active
A15: 14 | B15: Ctrl+B ▸ Shift+W | C15: rename_workspace | D15: Rename workspace | E15: Workspaces | F15: herdr | G15: Active
A16: 15 | B16: Ctrl+B ▸ Shift+D | C16: close_workspace | D16: Close workspace | E16: Workspaces | F16: herdr | G16: Active
A17: 16 | B17: Ctrl+B ▸ C | C17: new_tab | D17: New tab | E17: Tabs | F17: herdr | G17: Active
A18: 17 | B18: Ctrl+B ▸ Shift+T | C18: rename_tab | D18: Rename tab | E18: Tabs | F18: herdr | G18: Active
A19: 18 | B19: Ctrl+B ▸ P | C19: previous_tab | D19: Previous tab | E19: Tabs | F19: herdr | G19: Active
A20: 19 | B20: Ctrl+B ▸ N | C20: next_tab | D20: Next tab | E20: Tabs | F20: herdr | G20: Active
... A32: 31 | B32: Ctrl+B ▸ X | C32: close_pane | D32: Close pane | E32: Panes | F32: herdr | G32: Active
A33: 32 | B33: Ctrl+B ▸ Z | C33: zoom | D33: Zoom pane (fullscreen inside herdr) | E33: Panes | F33: herdr | G33: Active | I33: legacy alias: fullscreen
A34: 33 | B34: Ctrl+B ▸ R | C34: resize_mode | D34: Enter resize mode | E34: Panes | F34: herdr | G34: Active
A35: 34 | B35: Up | C35: navigate_workspace_up | D35: Navigate mode: workspace up | E35: Navigate mode | F35: herdr | G35: Active
A36: 35 | B36: Down | C36: navigate_workspace_down | D36: Navigate mode: workspace down | E36: Navigate mode | F36: herdr | G36: Active
A37: 36 | B37: H | C37: navigate_pane_left | D37: Navigate mode: pane left | E37: Navigate mode | F37: herdr | G37: Active | I37: left arrow always focuses the pane to the left
A38: 37 | B38: J | C38: navigate_pane_down | D38: Navigate mode: pane down | E38: Navigate mode | F38: herdr | G38: Active
A39: 38 | B39: K | C39: navigate_pane_up | D39: Navigate mode: pane up | E39: Navigate mode | F39: herdr | G39: Active
A40: 39 | B40: L | C40: navigate_pane_right | D40: Navigate mode: pane right | E40: Navigate mode | F40: herdr | G40: Active | I40: right arrow always focuses the pane to the right
A41: 40 | B41: Ctrl+B ▸ Alt+C | C41: keys.command | D41: Run ~/.local/bin/herdr-tabs | E41: Yours | F41: You | G41: Active | I41: From ~/.config/herdr/config.toml
A42: 41 | C42: open_worktree | D42: Open an existing worktree | E42: Workspaces | F42: herdr | G42: Not bound | I42: optional, unset by default
A43: 42 | C43: remove_worktree | D43: Remove a worktree (asks first) | E43: Workspaces | F43: herdr | G43: Not bound | I43: optional, unset by default; opens confirmation
A44: 43 | C44: previous_workspace | D44: Previous workspace | E44: Workspaces | F44: herdr | G44: Not bound | I44: optional, unset by default
A45: 44 | C45: next_workspace | D45: Next workspace | E45: Workspaces | F45: herdr | G45: Not bound | I45: optional, unset by default
A46: 45 | C46: switch_workspace | D46: Switch to workspace by number | E46: Workspaces | F46: herdr | G46: Not bound | I46: optional indexed binding, e.g. "prefix+shift+1..9"
A47: 46 | C47: move_tab_previous | D47: Move tab toward the front | E47: Tabs | F47: herdr | G47: Not bound | I47: optional, e.g. "alt+shift+left" moves the tab toward the front
A48: 47 | C48: move_tab_next | D48: Move tab toward the back | E48: Tabs | F48: herdr | G48: Not bound | I48: optional, e.g. "alt+shift+right" moves the tab toward the back
A49: 48 | C49: last_pane | D49: Last-used pane | E49: Panes | F49: herdr | G49: Not bound | I49: optional, unset by default; bind e.g. "prefix+tab" for global back-and-forth
A50: 49 | C50: resize_pane_left | D50: Resize pane left | E50: Panes | F50: herdr | G50: Not bound | I50: optional, e.g. "ctrl+shift+alt+left" resizes without entering resize mode
A51: 50 | C51: resize_pane_down | D51: Resize pane down | E51: Panes | F51: herdr | G51: Not bound | I51: optional, e.g. "ctrl+shift+alt+down"
...

Sheet Yabai
A1: # | B1: Shortcut | C1: What it does | D1: Group | E1: Keyboard | F1: Status | G1: Your call | H1: Notes
A2: 1 | B2: Alt + H | C2: Focus window left | D2: Focus | E2: MacBook | F2: Active
A3: 2 | B3: Alt + J | C3: Focus window down | D3: Focus | E3: MacBook | F3: Active
A4: 3 | B4: Alt + K | C4: Focus window up | D4: Focus | E4: MacBook | F4: Active
A5: 4 | B5: Alt + L | C5: Focus window right | D5: Focus | E5: MacBook | F5: Active
A6: 5 | B6: Ctrl + Alt + Cmd + H | C6: Focus window left | D6: Focus | E6: Lily58 | F6: Active
A7: 6 | B7: Ctrl + Alt + Cmd + J | C7: Focus window down | D7: Focus | E7: Lily58 | F7: Active
A8: 7 | B8: Ctrl + Alt + Cmd + K | C8: Focus window up | D8: Focus | E8: Lily58 | F8: Active
A9: 8 | B9: Ctrl + Alt + Cmd + L | C9: Focus window right | D9: Focus | E9: Lily58 | F9: Active
A10: 9 | B10: Ctrl + Cmd + H | C10: Focus window left | D10: Focus | E10: Omarchy-style | F10: Active
A11: 10 | B11: Ctrl + Cmd + J | C11: Focus window down | D11: Focus | E11: Omarchy-style | F11: Active
A12: 11 | B12: Ctrl + Cmd + K | C12: Focus window up | D12: Focus | E12: Omarchy-style | F12: Active
A13: 12 | B13: Ctrl + Cmd + L | C13: Focus window right | D13: Focus | E13: Omarchy-style | F13: Active
... A60: 59 | B60: Shift + Cmd + 9 | C60: Move window to desktop 9 and follow | D60: Desktops | E60: MacBook | F60: Active
